<?xml version="1.0" encoding="UTF-8"?>
<testng-results ignored="0" total="3" passed="1" failed="2" skipped="0">
  <reporter-output>
  </reporter-output>
  <suite started-at="2021-01-08T02:04:24Z" name="Suite" finished-at="2021-01-08T02:04:47Z" duration-ms="23569">
    <groups>
    </groups>
    <test started-at="2021-01-08T02:04:24Z" name="Test" finished-at="2021-01-08T02:04:47Z" duration-ms="23569">
      <class name="com.banking.testcases.TC02_LoginUsingExcelTest">
        <test-method is-config="true" signature="setUp()[pri:0, instance:com.banking.testcases.TC02_LoginUsingExcelTest@501edcf1]" started-at="2021-01-07T18:04:24Z" name="setUp" finished-at="2021-01-07T18:04:27Z" duration-ms="3421" status="PASS">
          <reporter-output>
          </reporter-output>
        </test-method> <!-- setUp -->
        <test-method signature="loginTest(java.lang.String, java.lang.String)[pri:0, instance:com.banking.testcases.TC02_LoginUsingExcelTest@501edcf1]" started-at="2021-01-07T18:04:28Z" name="loginTest" data-provider="excelLoginData" finished-at="2021-01-07T18:04:34Z" duration-ms="6203" status="FAIL">
          <params>
            <param index="0">
              <value>
                <![CDATA[invalid01]]>
              </value>
            </param>
            <param index="1">
              <value>
                <![CDATA[jahetAp]]>
              </value>
            </param>
          </params>
          <exception class="java.lang.AssertionError">
            <message>
              <![CDATA[expected [true] but found [false]]]>
            </message>
            <full-stacktrace>
              <![CDATA[java.lang.AssertionError: expected [true] but found [false]
	at org.testng.Assert.fail(Assert.java:93)
	at org.testng.Assert.failNotEquals(Assert.java:512)
	at org.testng.Assert.assertTrue(Assert.java:41)
	at org.testng.Assert.assertTrue(Assert.java:51)
	at com.banking.testcases.TC02_LoginUsingExcelTest.loginTest(TC02_LoginUsingExcelTest.java:35)
	at java.base/jdk.internal.reflect.NativeMethodAccessorImpl.invoke0(Native Method)
	at java.base/jdk.internal.reflect.NativeMethodAccessorImpl.invoke(NativeMethodAccessorImpl.java:62)
	at java.base/jdk.internal.reflect.DelegatingMethodAccessorImpl.invoke(DelegatingMethodAccessorImpl.java:43)
	at java.base/java.lang.reflect.Method.invoke(Method.java:567)
	at org.testng.internal.MethodInvocationHelper.invokeMethod(MethodInvocationHelper.java:108)
	at org.testng.internal.Invoker.invokeMethod(Invoker.java:661)
	at org.testng.internal.Invoker.invokeTestMethod(Invoker.java:869)
	at org.testng.internal.Invoker.invokeTestMethods(Invoker.java:1193)
	at org.testng.internal.TestMethodWorker.invokeTestMethods(TestMethodWorker.java:126)
	at org.testng.internal.TestMethodWorker.run(TestMethodWorker.java:109)
	at org.testng.TestRunner.privateRun(TestRunner.java:744)
	at org.testng.TestRunner.run(TestRunner.java:602)
	at org.testng.SuiteRunner.runTest(SuiteRunner.java:380)
	at org.testng.SuiteRunner.runSequentially(SuiteRunner.java:375)
	at org.testng.SuiteRunner.privateRun(SuiteRunner.java:340)
	at org.testng.SuiteRunner.run(SuiteRunner.java:289)
	at org.testng.SuiteRunnerWorker.runSuite(SuiteRunnerWorker.java:52)
	at org.testng.SuiteRunnerWorker.run(SuiteRunnerWorker.java:86)
	at org.testng.TestNG.runSuitesSequentially(TestNG.java:1301)
	at org.testng.TestNG.runSuitesLocally(TestNG.java:1226)
	at org.testng.TestNG.runSuites(TestNG.java:1144)
	at org.testng.TestNG.run(TestNG.java:1115)
	at org.testng.remote.AbstractRemoteTestNG.run(AbstractRemoteTestNG.java:115)
	at org.testng.remote.RemoteTestNG.initAndRun(RemoteTestNG.java:251)
	at org.testng.remote.RemoteTestNG.main(RemoteTestNG.java:77)
]]>
            </full-stacktrace>
          </exception> <!-- java.lang.AssertionError -->
          <reporter-output>
          </reporter-output>
        </test-method> <!-- loginTest -->
        <test-method signature="loginTest(java.lang.String, java.lang.String)[pri:0, instance:com.banking.testcases.TC02_LoginUsingExcelTest@501edcf1]" started-at="2021-01-07T18:04:34Z" name="loginTest" data-provider="excelLoginData" finished-at="2021-01-07T18:04:41Z" duration-ms="6325" status="PASS">
          <params>
            <param index="0">
              <value>
                <![CDATA[mngr302754]]>
              </value>
            </param>
            <param index="1">
              <value>
                <![CDATA[sahabUt]]>
              </value>
            </param>
          </params>
          <reporter-output>
          </reporter-output>
        </test-method> <!-- loginTest -->
        <test-method signature="loginTest(java.lang.String, java.lang.String)[pri:0, instance:com.banking.testcases.TC02_LoginUsingExcelTest@501edcf1]" started-at="2021-01-07T18:04:41Z" name="loginTest" data-provider="excelLoginData" finished-at="2021-01-07T18:04:46Z" duration-ms="5422" status="FAIL">
          <params>
            <param index="0">
              <value>
                <![CDATA[invalid02]]>
              </value>
            </param>
            <param index="1">
              <value>
                <![CDATA[bAdYvyb]]>
              </value>
            </param>
          </params>
          <exception class="java.lang.AssertionError">
            <message>
              <![CDATA[expected [true] but found [false]]]>
            </message>
            <full-stacktrace>
              <![CDATA[java.lang.AssertionError: expected [true] but found [false]
	at org.testng.Assert.fail(Assert.java:93)
	at org.testng.Assert.failNotEquals(Assert.java:512)
	at org.testng.Assert.assertTrue(Assert.java:41)
	at org.testng.Assert.assertTrue(Assert.java:51)
	at com.banking.testcases.TC02_LoginUsingExcelTest.loginTest(TC02_LoginUsingExcelTest.java:35)
	at java.base/jdk.internal.reflect.NativeMethodAccessorImpl.invoke0(Native Method)
	at java.base/jdk.internal.reflect.NativeMethodAccessorImpl.invoke(NativeMethodAccessorImpl.java:62)
	at java.base/jdk.internal.reflect.DelegatingMethodAccessorImpl.invoke(DelegatingMethodAccessorImpl.java:43)
	at java.base/java.lang.reflect.Method.invoke(Method.java:567)
	at org.testng.internal.MethodInvocationHelper.invokeMethod(MethodInvocationHelper.java:108)
	at org.testng.internal.Invoker.invokeMethod(Invoker.java:661)
	at org.testng.internal.Invoker.invokeTestMethod(Invoker.java:869)
	at org.testng.internal.Invoker.invokeTestMethods(Invoker.java:1193)
	at org.testng.internal.TestMethodWorker.invokeTestMethods(TestMethodWorker.java:126)
	at org.testng.internal.TestMethodWorker.run(TestMethodWorker.java:109)
	at org.testng.TestRunner.privateRun(TestRunner.java:744)
	at org.testng.TestRunner.run(TestRunner.java:602)
	at org.testng.SuiteRunner.runTest(SuiteRunner.java:380)
	at org.testng.SuiteRunner.runSequentially(SuiteRunner.java:375)
	at org.testng.SuiteRunner.privateRun(SuiteRunner.java:340)
	at org.testng.SuiteRunner.run(SuiteRunner.java:289)
	at org.testng.SuiteRunnerWorker.runSuite(SuiteRunnerWorker.java:52)
	at org.testng.SuiteRunnerWorker.run(SuiteRunnerWorker.java:86)
	at org.testng.TestNG.runSuitesSequentially(TestNG.java:1301)
	at org.testng.TestNG.runSuitesLocally(TestNG.java:1226)
	at org.testng.TestNG.runSuites(TestNG.java:1144)
	at org.testng.TestNG.run(TestNG.java:1115)
	at org.testng.remote.AbstractRemoteTestNG.run(AbstractRemoteTestNG.java:115)
	at org.testng.remote.RemoteTestNG.initAndRun(RemoteTestNG.java:251)
	at org.testng.remote.RemoteTestNG.main(RemoteTestNG.java:77)
]]>
            </full-stacktrace>
          </exception> <!-- java.lang.AssertionError -->
          <reporter-output>
          </reporter-output>
        </test-method> <!-- loginTest -->
        <test-method is-config="true" signature="tearDrow()[pri:0, instance:com.banking.testcases.TC02_LoginUsingExcelTest@501edcf1]" started-at="2021-01-07T18:04:46Z" name="tearDrow" finished-at="2021-01-07T18:04:47Z" duration-ms="986" status="PASS">
          <reporter-output>
          </reporter-output>
        </test-method> <!-- tearDrow -->
      </class> <!-- com.banking.testcases.TC02_LoginUsingExcelTest -->
    </test> <!-- Test -->
  </suite> <!-- Suite -->
</testng-results>
